<?xml version="1.0"?>
<robot name="physics">

  <link name="world"/>
  <!-- Fixed Based Joint -->
  <joint name="RXYZ" type="fixed">
    <origin rpy="0.0 0.0 0.0" xyz="0.0 0.0 1.3"/>
    <parent link="world"/>
    <child link="slideBar"/>
  </joint>

  <link name="slideBar">
    <visual>
      <geometry>
        <box size="10 0.05 0.05"/>
      </geometry>
      <origin xyz="0 0 0"/>
      <material name="green">
        <color rgba="0 0.8 .8 1"/>
      </material>
    </visual>
    <inertial>
      <mass value="0"/>
      <inertia ixx="1.0" ixy="0.0" ixz="0.0" iyy="1.0" iyz="0.0" izz="1.0"/>
    </inertial>
  </link>

  <link name="cart">
    <visual>
      <geometry>
        <box size="0.5 0.2 0.1"/>
      </geometry>
      <origin xyz="0 0 0"/>
      <material name="blue">
        <color rgba="0 0 .8 1"/>
      </material>
    </visual>
    <collision>
      <geometry>
        <box size="0.5 0.2 0.1"/>
      </geometry>
      <origin xyz="0 0 0"/>
    </collision>
    <inertial>
      <mass value="1"/>
      <inertia ixx="1.0" ixy="0.0" ixz="0.0" iyy="1.0" iyz="0.0" izz="1.0"/>
    </inertial>
  </link>

  <joint name="slider_to_cart" type="prismatic">
    <axis xyz="1 0 0"/>
    <origin xyz="0.0 0.0 0.0"/>
    <parent link="slideBar"/>
    <child link="cart"/>
    <dynamics damping="0.0" friction="0.0"/>
  </joint>

  <link name="pole">
    <visual>
      <geometry>
        <cylinder radius="0.02"  length="1.0"/>
      </geometry>
      <origin rpy="0 0 0" xyz="0 0 0.5"/>
      <material name="white">
        <color rgba="1 1 1 1"/>
      </material>
    </visual>
    <visual>
      <geometry>
        <sphere radius="0.075"/>
      </geometry>
      <origin rpy="0 0 0" xyz="0 0 1.0"/>
      <material name="white">
        <color rgba="1 1 1 1"/>
      </material>
    </visual>

    <inertial>
      <origin xyz="0 0 1.0"/>
      <mass value="0.1"/>
      <inertia ixx="0.0" ixy="0.0" ixz="0.0" iyy="0.0" iyz="0.0" izz="0.0"/>
    </inertial>
    <collision>
      <geometry>
        <cylinder radius="0.02"  length="1.0"/>
      </geometry>
      <origin rpy="0 0 0" xyz="0 0 0.5"/>
    </collision>
    <collision>
      <geometry>
        <sphere radius="0.075"/>
      </geometry>
      <origin rpy="0 0 0" xyz="0 0 1.0"/>
    </collision>
  </link>

  <joint name="cart_to_pole" type="continuous">
    <axis xyz="0 1 0"/>
    <origin xyz="0.0 0.0 0"/>
    <parent link="cart"/>
    <child link="pole"/>
    <dynamics damping="0.0" friction="0.0"/>
  </joint>

</robot>
